Workbook

Sheet 📊 HR Dashboard
A1: HR & EMPLOYEE PERFORMANCE DASHBOARD | FY 2026
A3: Farhan Siddique | Virtual Assistant & Data Specialist | May 2026
A4: People Analytics | Workforce Insights | Performance Management | Live data from 'Employee Data' sheet
A6: Total Headcount | C6: Total Payroll | E6: Avg Salary | G6: Avg Performance | I6: Avg Attendance % | K6: Avg Tenure (yrs) | M6: Training Hrs/Emp | O6: Turnover Rate
A7: =COUNTA('Employee Data'!A2:A101) | C7: =SUM('Employee Data'!F2:F101) | E7: =AVERAGE('Employee Data'!F2:F101) | G7: =AVERAGE('Employee Data'!L2:L101) | I7: =AVERAGE('Employee Data'!M2:M101) | K7: =AVERAGE('Employee Data'!E2:E101) | M7: =AVERAGE('Employee Data'!N2:N101) | O7: =COUNTIF('Employee Data'!P2:P101,"Resigned")/COUNTA('Employee Data'!A2:A101)
A10: DEPARTMENT PERFORMANCE SUMMARY
A11: Department | B11: Headcount | C11: Total Salary | D11: Avg Salary | E11: Avg Performance | F11: Avg Attendance | G11: Training Hrs | H11: Open Roles | I11: Budget Util% | J11: Turnover | K11: Promotions | L11: Score
A12: Engineering | B12: 22 | C12: 2640000 | D12: =IFERROR(C11/B11,0) | E12: 1.0061519 | F12: 0.90895481 | G12: 30 | H12: 2 | I12: 0.97833257 | J12: 0.047039152 | K12: 1 | L12: =ROUND((E11/5*0.4+F11*0.3+I11*0.3)*10,1)
A13: Marketing | B13: 14 | C13: 1260000 | D13: =IFERROR(C12/B12,0) | E13: 0.79438697 | F13: 0.96427831 | G13: 48 | H13: 1 | I13: 0.92601063 | J13: 0.028875564 | K13: 2 | L13: =ROUND((E12/5*0.4+F12*0.3+I12*0.3)*10,1)
A14: Sales | B14: 18 | C14: 1890000 | D14: =IFERROR(C13/B13,0) | E14: 1.1216571 | F14: 0.95295837 | G14: 30 | H14: 3 | I14: 0.92852896 | J14: 0.031656262 | K14: 3 | L14: =ROUND((E13/5*0.4+F13*0.3+I13*0.3)*10,1)
A15: Finance | B15: 8 | C15: 880000 | D15: =IFERROR(C14/B14,0) | E15: 0.82436516 | F15: 0.88810179 | G15: 42 | H15: 0 | I15: 0.99211023 | J15: 0.10223274 | K15: 1 | L15: =ROUND((E14/5*0.4+F14*0.3+I14*0.3)*10,1)
A16: HR | B16: 6 | C16: 540000 | D16: =IFERROR(C15/B15,0) | E16: 0.69107916 | F16: 0.93844237 | G16: 36 | H16: 1 | I16: 0.94362551 | J16: 0.11322062 | K16: 0 | L16: =ROUND((E15/5*0.4+F15*0.3+I15*0.3)*10,1)
A17: Operations | B17: 12 | C17: 1080000 | D17: =IFERROR(C16/B16,0) | E17: 0.93565538 | F17: 0.97847633 | G17: 26 | H17: 2 | I17: 0.99808653 | J17: 0.046392445 | K17: 1 | L17: =ROUND((E16/5*0.4+F16*0.3+I16*0.3)*10,1)
A18: Customer Success | B18: 10 | C18: 900000 | D18: =IFERROR(C17/B17,0) | E18: 1.0955179 | F18: 0.88834247 | G18: 35 | H18: 1 | I18: 0.98508276 | J18: 0.028220289 | K18: 2 | L18: =ROUND((E17/5*0.4+F17*0.3+I17*0.3)*10,1)
A19: Product | B19: 8 | C19: 960000 | D19: =IFERROR(C18/B18,0) | E19: 1.0318294 | F19: 0.89038621 | G19: 32 | H19: 1 | I19: 0.89800685 | J19: 0.089522484 | K19: 1 | L19: =ROUND((E18/5*0.4+F18*0.3+I18*0.3)*10,1)
A20: Legal | B20: 4 | C20: 560000 | D20: =IFERROR(C19/B19,0) | E20: 0.85268071 | F20: 0.916036 | G20: 33 | H20: 0 | I20: 0.97624124 | J20: 0.040345731 | K20: 0 | L20: =ROUND((E19/5*0.4+F19*0.3+I19*0.3)*10,1)
A21: Executive | B21: 3 | C21: 750000 | D21: =IFERROR(C20/B20,0) | E21: 1.0853629 | F21: 0.94325636 | G21: 27 | H21: 0 | I21: 0.95209742 | J21: 0.099790354 | K21: 1 | L21: =ROUND((E20/5*0.4+F20*0.3+I20*0.3)*10,1)
A22: R&D | B22: 7 | C22: 840000 | D22: =IFERROR(C21/B21,0) | E22: 1.0538306 | F22: 0.95310689 | G22: 24 | H22: 1 | I22: 0.9801045 | J22: 0.086314198 | K22: 1 | L22: =ROUND((E21/5*0.4+F21*0.3+I21*0.3)*10,1)
A23: IT Support | B23: 5 | C23: 400000 | D23: =IFERROR(C22/B22,0) | E23: 0.82242979 | F23: 0.92330714 | G23: 39 | H23: 1 | I23: 0.9820898 | J23: 0.11081161 | K23: 0 | L23: =ROUND((E22/5*0.4+F22*0.3+I22*0.3)*10,1)
A25: PERFORMANCE RATING DISTRIBUTION | H25: SALARY BAND ANALYSIS
A26: Rating | B26: Label | C26: Count | D26: % of Workforce | E26: Avg Salary | F26: Avg Tenure | H26: Band | I26: Range | J26: Headcount | K26: % Staff | L26: Avg Perf | M26: Budget $
A27: 5 | B27: Outstanding | C27: 12 | D27: =C26/SUM(C26:C30) | E27: 110223 | F27: 7.7 | H27: Band 1 | I27: $30K–$50K | J27: 12 | K27: =IFERROR(J26/SUM(J26:J31),0) | L27: 3.2 | M27: 2340000
A28: 4 | B28: Exceeds Expectations | C28: 28 | D28: =C27/SUM(C26:C30) | E28: 105464 | F28: 6.2 | H28: Band 2 | I28: $50K–$75K | J28: 28 | K28: =IFERROR(J27/SUM(J26:J31),0) | L28: 3.5 | M28: 5880000
A29: 3 | B29: Meets Expectations | C29: 38 | D29: =C28/SUM(C26:C30) | E29: 92527 | F29: 4.9 | H29: Band 3 | I29: $75K–$100K | J29: 32 | K29: =IFERROR(J28/SUM(J26:J31),0) | L29: 3.7 | M29: 7680000
A30: 2 | B30: Needs Improvement | C30: 16 | D30: =C29/SUM(C26:C30) | E30: 82276 | F30: 3.6 | H30: Band 4 | I30: $100K–$150K | J30: 18 | K30: =IFERROR(J29/SUM(J26:J31),0) | L30: 3.9 | M30: 4860000
A31: 1 | B31: Unsatisfactory | C31: 6 | D31: =C30/SUM(C26:C30) | E31: 62975 | F31: 2.5 | H31: Band 5 | I31: $150K–$200K | J31: 7 | K31: =IFERROR(J30/SUM(J26:J31),0) | L31: 4.1 | M31: 2450000
H32: Band 6 | I32: $200K+ | J32: 3 | K32: =IFERROR(J31/SUM(J26:J31),0) | L32: 4.4 | M32: 1950000
A34: TRAINING & DEVELOPMENT TRACKER
A35: Department | B35: Mandatory Hrs | C35: Completed Hrs | D35: Completion% | E35: Budget | F35: Spent | G35: Budget Util% | H35: Certifications | I35: Avg Score | J35: Next Due | K35: Status
A36: Engineering | B36: 40 | C36: 38 | D36: =IFERROR(C35/B35,0) | E36: 9500 | F36: 8750 | G36: =IFERROR(F35/E35,0) | H36: 14 | I36: 88 | J36: 2025-09-01 | K36: =IF(D35>=1,"✅ Complete",IF(D35>=0.8,"⚠️ In Progress","❌ Behind"))
A37: Marketing | B37: 24 | C37: 22 | D37: =IFERROR(C36/B36,0) | E37: 5200 | F37: 4800 | G37: =IFERROR(F36/E36,0) | H37: 8 | I37: 91 | J37: 2025-09-16 | K37: =IF(D36>=1,"✅ Complete",IF(D36>=0.8,"⚠️ In Progress","❌ Behind"))
A38: Sales | B38: 32 | C38: 28 | D38: =IFERROR(C37/B37,0) | E38: 7200 | F38: 6500 | G38: =IFERROR(F37/E37,0) | H38: 11 | I38: 84 | J38: 2025-10-01 | K38: =IF(D37>=1,"✅ Complete",IF(D37>=0.8,"⚠️ In Progress","❌ Behind"))
A39: Finance | B39: 20 | C39: 20 | D39: =IFERROR(C38/B38,0) | E39: 4400 | F39: 4200 | G39: =IFERROR(F38/E38,0) | H39: 5 | I39: 95 | J39: 2025-10-16 | K39: =IF(D38>=1,"✅ Complete",IF(D38>=0.8,"⚠️ In Progress","❌ Behind"))
A40: HR | B40: 28 | C40: 25 | D40: =IFERROR(C39/B39,0) | E40: 3600 | F40: 3100 | G40: =IFERROR(F39/E39,0) | H40: 7 | I40: 89 | J40: 2025-10-31 | K40: =IF(D39>=1,"✅ Complete",IF(D39>=0.8,"⚠️ In Progress","❌ Behind"))
A41: Operations | B41: 36 | C41: 30 | D41: =IFERROR(C40/B40,0) | E41: 6800 | F41: 6200 | G41: =IFERROR(F40/E40,0) | H41: 9 | I41: 86 | J41: 2025-11-15 | K41: =IF(D40>=1,"✅ Complete",IF(D40>=0.8,"⚠️ In Progress","❌ Behind"))
A42: Customer Success | B42: 20 | C42: 19 | D42: =IFERROR(C41/B41,0) | E42: 4000 | F42: 3800 | G42: =IFERROR(F41/E41,0) | H42: 6 | I42: 92 | J42: 2025-11-30 | K42: =IF(D41>=1,"✅ Complete",IF(D41>=0.8,"⚠️ In Progress","❌ Behind"))
A43: Product | B43: 28 | C43: 27 | D43: =IFERROR(C42/B42,0) | E43: 5600 | F43: 5400 | G43: =IFERROR(F42/E42,0) | H43: 8 | I43: 90 | J43: 2025-12-15 | K43: =IF(D42>=1,"✅ Complete",IF(D42>=0.8,"⚠️ In Progress","❌ Behind"))
A44: Legal | B44: 16 | C44: 16 | D44: =IFERROR(C43/B43,0) | E44: 3200 | F44: 3100 | G44: =IFERROR(F43/E43,0) | H44: 3 | I44: 97 | J44: 2025-12-30 | K44: =IF(D43>=1,"✅ Complete",IF(D43>=0.8,"⚠️ In Progress","❌ Behind"))
A45: Executive | B45: 12 | C45: 12 | D45: =IFERROR(C44/B44,0) | E45: 2800 | F45: 2800 | G45: =IFERROR(F44/E44,0) | H45: 2 | I45: 100 | J45: 2026-01-14 | K45: =IF(D44>=1,"✅ Complete",IF(D44>=0.8,"⚠️ In Progress","❌ Behind"))
A46: R&D | B46: 32 | C46: 29 | D46: =IFERROR(C45/B45,0) | E46: 6000 | F46: 5600 | G46: =IFERROR(F45/E45,0) | H46: 10 | I46: 87 | J46: 2026-01-29 | K46: =IF(D45>=1,"✅ Complete",IF(D45>=0.8,"⚠️ In Progress","❌ Behind"))
...

Sheet Employee Data
A1: Emp ID | B1: Full Name | C1: Department | D1: Job Title | E1: Tenure (yrs) | F1: Base Salary | G1: Bonus | H1: Total Comp | I1: Manager | J1: Gender | K1: Age | L1: Performance (1-5) | M1: Attendance % | N1: Training Hrs | O1: Certifications | P1: Status | Q1: Start Date | R1: Location | S1: Education | T1: Notes
A2: EMP1000 | B2: James Smith | C2: Marketing | D2: Marketing Specialist | E2: 6.8 | F2: 98000 | G2: 16000 | H2: =F2+G2 | I2: Paul COO | J2: Non-binary | K2: 55 | L2: 5 | M2: 0.953 | N2: 73 | O2: 0 | P2: Active | Q2: 2019-02-02 | R2: Toronto | S2: Bachelor's | T2: High potential
A3: EMP1001 | B3: Mary Johnson | C3: Sales | D3: Business Dev Rep | E3: 3 | F3: 86000 | G3: 7500 | H3: =F3+G3 | I3: Amy VP-Eng | J3: Non-binary | K3: 27 | L3: 4 | M3: 0.852 | N3: 68 | O3: 2 | P3: Active | Q3: 2013-09-03 | R3: London | S3: Bachelor's | T3: High potential
A4: EMP1002 | B4: Robert Williams | C4: Marketing | D4: Marketing Specialist | E4: 7.3 | F4: 80000 | G4: 4500 | H4: =F4+G4 | I4: Kat VP-Prod | J4: Non-binary | K4: 27 | L4: 2 | M4: 0.929 | N4: 46 | O4: 3 | P4: Active | Q4: 2016-06-19 | R4: Austin | S4: MBA | T4: PIP recommended
A5: EMP1003 | B5: Patricia Brown | C5: Sales | D5: Business Dev Rep | E5: 4 | F5: 74000 | G5: 12500 | H5: =F5+G5 | I5: Jane CEO | J5: Non-binary | K5: 57 | L5: 3 | M5: 0.978 | N5: 54 | O5: 2 | P5: Active | Q5: 2014-01-06 | R5: San Francisco | S5: Bachelor's | T5: Standard performer
A6: EMP1004 | B6: John Jones | C6: IT Support | D6: Security Analyst | E6: 9.9 | F6: 52000 | G6: 8500 | H6: =F6+G6 | I6: Sara CFO | J6: Female | K6: 58 | L6: 5 | M6: 0.87 | N6: 61 | O6: 3 | P6: Active | Q6: 2019-12-05 | R6: Chicago | S6: Bachelor's | T6: High potential
A7: EMP1005 | B7: Jennifer Garcia | C7: Engineering | D7: Lead Engineer | E7: 0.7 | F7: 94000 | G7: 6000 | H7: =F7+G7 | I7: Rex VP-Mktg | J7: Female | K7: 36 | L7: 3 | M7: 0.873 | N7: 51 | O7: 1 | P7: Active | Q7: 2018-03-05 | R7: Toronto | S7: Associate's | T7: Standard performer
A8: EMP1006 | B8: Michael Miller | C8: Sales | D8: Sales Rep | E8: 9.5 | F8: 77000 | G8: 10000 | H8: =F8+G8 | I8: Rex VP-Mktg | J8: Non-binary | K8: 34 | L8: 4 | M8: 0.961 | N8: 75 | O8: 5 | P8: Active | Q8: 2016-07-31 | R8: San Francisco | S8: MBA | T8: High potential
A9: EMP1007 | B9: Linda Davis | C9: HR | D9: HRBP | E9: 7.2 | F9: 70000 | G9: 7500 | H9: =F9+G9 | I9: Paul COO | J9: Male | K9: 30 | L9: 3 | M9: 0.964 | N9: 64 | O9: 4 | P9: Active | Q9: 2016-11-28 | R9: Chicago | S9: PhD | T9: Standard performer
A10: EMP1008 | B10: David Wilson | C10: Operations | D10: Supply Chain Lead | E10: 11.8 | F10: 94000 | G10: 12000 | H10: =F10+G10 | I10: Tom VP-Sales | J10: Male | K10: 34 | L10: 5 | M10: 0.845 | N10: 49 | O10: 2 | P10: Active | Q10: 2018-03-15 | R10: Chicago | S10: Associate's | T10: High potential
A11: EMP1009 | B11: Barbara Taylor | C11: Legal | D11: Contract Manager | E11: 1.6 | F11: 89000 | G11: 9000 | H11: =F11+G11 | I11: Amy VP-Eng | J11: Male | K11: 22 | L11: 3 | M11: 0.883 | N11: 25 | O11: 4 | P11: Active | Q11: 2019-04-05 | R11: London | S11: MBA | T11: Standard performer
A12: EMP1010 | B12: Richard Anderson | C12: HR | D12: HRBP | E12: 11.7 | F12: 88000 | G12: 8000 | H12: =F12+G12 | I12: Paul COO | J12: Non-binary | K12: 42 | L12: 5 | M12: 0.953 | N12: 44 | O12: 0 | P12: Active | Q12: 2023-11-18 | R12: London | S12: Bachelor's | T12: High potential
A13: EMP1011 | B13: Susan Thomas | C13: Customer Success | D13: CS Director | E13: 6.7 | F13: 61000 | G13: 8000 | H13: =F13+G13 | I13: Rex VP-Mktg | J13: Non-binary | K13: 23 | L13: 3 | M13: 0.906 | N13: 15 | O13: 2 | P13: Active | Q13: 2016-05-13 | R13: Remote | S13: Bachelor's | T13: Standard performer
... A101: EMP1099 | B101: Laura Walker | C101: Sales | D101: Sales Manager | E101: 4.6 | F101: 100000 | G101: 18000 | H101: =F101+G101 | I101: Jane CEO | J101: Male | K101: 51 | L101: 2 | M101: 0.847 | N101: 74 | O101: 3 | P101: Active | Q101: 2023-04-15 | R101: London | S101: Bachelor's | T101: PIP recommended

Sheet Compensation Analysis
A1: COMPENSATION ANALYSIS | Pay Equity & Band Review
A2: Department | B2: Min Salary | C2: Max Salary | D2: Avg Salary | E2: Median Salary | F2: Std Dev | G2: Pay Gap (M/F) | H2: Budget Allocated | I2: Budget Used | J2: Budget Remaining
A3: Engineering | B3: 65000 | C3: 145000 | D3: 98000 | E3: 95000 | F3: 18500 | G3: 0.96 | H3: 2200000 | I3: 2200000 | J3: =H3-I3
A4: Marketing | B4: 55000 | C4: 110000 | D4: 72000 | E4: 70000 | F4: 12000 | G4: 0.93 | H4: 1050000 | I4: 1050000 | J4: =H4-I4
A5: Sales | B5: 60000 | C5: 130000 | D5: 78000 | E5: 76000 | F5: 15000 | G5: 0.94 | H5: 1540000 | I5: 1540000 | J5: =H5-I5
A6: Finance | B6: 72000 | C6: 140000 | D6: 85000 | E6: 83000 | F6: 16000 | G6: 0.97 | H6: 680000 | I6: 680000 | J6: =H6-I6
A7: HR | B7: 50000 | C7: 95000 | D7: 65000 | E7: 63000 | F7: 11000 | G7: 0.95 | H7: 390000 | I7: 390000 | J7: =H7-I7
A8: Operations | B8: 58000 | C8: 115000 | D8: 70000 | E8: 68000 | F8: 12500 | G8: 0.94 | H8: 840000 | I8: 840000 | J8: =H8-I8
A9: Customer Success | B9: 52000 | C9: 105000 | D9: 68000 | E9: 66000 | F9: 11500 | G9: 0.96 | H9: 680000 | I9: 680000 | J9: =H9-I9
A10: Product | B10: 75000 | C10: 155000 | D10: 90000 | E10: 88000 | F10: 19000 | G10: 0.95 | H10: 720000 | I10: 720000 | J10: =H10-I10
A11: Legal | B11: 80000 | C11: 160000 | D11: 95000 | E11: 93000 | F11: 20000 | G11: 0.98 | H11: 380000 | I11: 380000 | J11: =H11-I11
A12: Executive | B12: 120000 | C12: 250000 | D12: 150000 | E12: 145000 | F12: 35000 | G12: 0.97 | H12: 450000 | I12: 450000 | J12: =H12-I12
A13: R&D | B13: 80000 | C13: 165000 | D13: 100000 | E13: 98000 | F13: 22000 | G13: 0.96 | H13: 700000 | I13: 700000 | J13: =H13-I13
A14: IT Support | B14: 48000 | C14: 95000 | D14: 62000 | E14: 60000 | F14: 10000 | G14: 0.93 | H14: 310000 | I14: 310000 | J14: =H14-I14

Sheet Recruitment Pipeline
A1: RECRUITMENT PIPELINE | Talent Acquisition Dashboard
A2: Req ID | B2: Role | C2: Department | D2: Level | E2: Applications | F2: Phone Screen | G2: Technical | H2: Final Round | I2: Offers | J2: Accepts | K2: Time to Fill (days) | L2: Status
A3: REQ-2025001 | B3: Senior Software Engineer | C3: Engineering | D3: Junior | E3: 176 | F3: 98 | G3: 67 | H3: 31 | I3: 18 | J3: 13 | K3: 75 | L3: Offer Extended
A4: REQ-2025002 | B4: Marketing Manager | C4: Marketing | D4: Mid | E4: 81 | F4: 36 | G4: 23 | H4: 9 | I4: 5 | J4: 4 | K4: 32 | L4: Active
A5: REQ-2025003 | B5: Sales Executive | C5: Sales | D5: Senior | E5: 75 | F5: 26 | G5: 17 | H5: 7 | I5: 4 | J5: 3 | K5: 73 | L5: Active
A6: REQ-2025004 | B6: Financial Analyst | C6: Finance | D6: Lead | E6: 152 | F6: 56 | G6: 38 | H6: 17 | I6: 10 | J6: 8 | K6: 35 | L6: Offer Extended
A7: REQ-2025005 | B7: HR Business Partner | C7: HR | D7: Manager | E7: 76 | F7: 29 | G7: 16 | H7: 8 | I7: 6 | J7: 4 | K7: 49 | L7: Active
A8: REQ-2025006 | B8: Operations Manager | C8: Operations | D8: Director | E8: 33 | F8: 19 | G8: 12 | H8: 5 | I8: 2 | J8: 2 | K8: 38 | L8: Offer Extended
A9: REQ-2025007 | B9: Customer Success Manager | C9: Customer Success | D9: VP | E9: 175 | F9: 85 | G9: 55 | H9: 22 | I9: 11 | J9: 8 | K9: 44 | L9: Active
A10: REQ-2025008 | B10: Product Manager | C10: Product | D10: Junior | E10: 66 | F10: 28 | G10: 11 | H10: 5 | I10: 4 | J10: 3 | K10: 70 | L10: Active
A11: REQ-2025009 | B11: Legal Counsel | C11: Legal | D11: Mid | E11: 67 | F11: 39 | G11: 21 | H11: 7 | I11: 5 | J11: 3 | K11: 51 | L11: Active
A12: REQ-2025010 | B12: Executive Assistant | C12: Executive | D12: Senior | E12: 43 | F12: 14 | G12: 7 | H12: 3 | I12: 2 | J12: 1 | K12: 44 | L12: Active
A13: REQ-2025011 | B13: Data Scientist | C13: R&D | D13: Lead | E13: 72 | F13: 27 | G13: 12 | H13: 6 | I13: 5 | J13: 4 | K13: 47 | L13: Active
A14: REQ-2025012 | B14: IT Security Analyst | C14: IT Support | D14: Manager | E14: 126 | F14: 74 | G14: 30 | H14: 10 | I14: 7 | J14: 5 | K14: 45 | L14: Active
... A32: REQ-2025030 | B32: Supply Chain Analyst | C32: Operations | D32: Mid | E32: 179 | F32: 106 | G32: 59 | H32: 27 | I32: 21 | J32: 13 | K32: 73 | L32: Active

Sheet ⚙️ Settings
A1: HR DASHBOARD SETTINGS & BENCHMARKS
A3: Setting | B3: Value | C3: Description
A4: Target Headcount | B4: 100 | C4: Full year staffing goal
A5: Annual HR Budget | B5: 9500000 | C5: Total HR & compensation budget
A6: Target Turnover Rate | B6: 0.1 | C6: Acceptable annual turnover %
A7: Target Attendance Rate | B7: 0.95 | C7: Minimum attendance benchmark
A8: Bonus Rate (Avg) | B8: 0.12 | C8: Average bonus as % of salary
A9: Training Budget/Employee | B9: 800 | C9: Annual training spend per person
A10: Target Performance Score | B10: 3.5 | C10: Average target on 1-5 scale
A11: Hiring Target (Annual) | B11: 20 | C11: Number of new hires planned
A12: Time to Fill Target (days) | B12: 35 | C12: Benchmark days to fill a role
A13: Employee NPS Target | B13: 45 | C13: Target eNPS score
A14: Promotion Rate Target | B14: 0.08 | C14: % of workforce promoted annually
A15: Diversity Target (%)_Women | B15: 0.45 | C15: Target female representation
