Workbook

Sheet 📊 Marketing Dashboard
A1: MARKETING CAMPAIGN ROI DASHBOARD | FY 2026
A3: Farhan Siddique | Virtual Assistant & Data Specialist | May 2026
A4: Multi-Channel Performance Analytics | ROI, CAC, CLV & Attribution Analysis | Live data from Campaign Data sheet
A6: Total Spend | C6: Total Revenue | E6: Overall ROI | G6: Total Leads | I6: Total Conversions | K6: Avg Conv Rate | M6: Avg CPC | O6: Avg CPA
A7: =SUM('Campaign Data'!F2:F201) | C7: =SUM('Campaign Data'!G2:G201) | E7: =IFERROR((SUM('Campaign Data'!G2:G201)-SUM('Campaign Data'!F2:F201))/SUM('Campaign Data'!F2:F201),0) | G7: =SUM('Campaign Data'!H2:H201) | I7: =SUM('Campaign Data'!I2:I201) | K7: =IFERROR(SUM('Campaign Data'!I2:I201)/SUM('Campaign Data'!H2:H201),0) | M7: =IFERROR(SUM('Campaign Data'!F2:F201)/SUM('Campaign Data'!J2:J201),0) | O7: =IFERROR(SUM('Campaign Data'!F2:F201)/SUM('Campaign Data'!I2:I201),0)
A10: CHANNEL PERFORMANCE SUMMARY
A11: Channel | B11: Spend | C11: Revenue | D11: ROI | E11: Leads | F11: Conversions | G11: Conv Rate | H11: Impressions | I11: Clicks | J11: CTR | K11: CPC | L11: CPA | M11: CLV | N11: ROAS
A12: Google Ads | B12: 185000 | C12: 620000 | D12: =IFERROR((C11-B11)/B11,0) | E12: 4200 | F12: 650 | G12: =IFERROR(F11/E11,0) | H12: 892000 | I12: 22400 | J12: 0.025112108 | K12: 8.2589286 | L12: 284.61538 | M12: 850 | N12: 3.3513514
A13: Facebook Ads | B13: 145000 | C13: 460000 | D13: =IFERROR((C12-B12)/B12,0) | E13: 5800 | F13: 820 | G13: =IFERROR(F12/E12,0) | H13: 1250000 | I13: 31500 | J13: 0.0252 | K13: 4.6031746 | L13: 176.82927 | M13: 720 | N13: 3.1724138
A14: LinkedIn Ads | B14: 95000 | C14: 350000 | D14: =IFERROR((C13-B13)/B13,0) | E14: 2100 | F14: 280 | G14: =IFERROR(F13/E13,0) | H14: 420000 | I14: 8500 | J14: 0.020238095 | K14: 11.176471 | L14: 339.28571 | M14: 1100 | N14: 3.6842105
A15: Email Marketing | B15: 32000 | C15: 280000 | D15: =IFERROR((C14-B14)/B14,0) | E15: 6500 | F15: 940 | G15: =IFERROR(F14/E14,0) | H15: 0 | I15: 0 | J15: 0 | K15: 0 | L15: 34.042553 | M15: 650 | N15: 8.75
A16: SEO/Organic | B16: 18000 | C16: 420000 | D16: =IFERROR((C15-B15)/B15,0) | E16: 3800 | F16: 580 | G16: =IFERROR(F15/E15,0) | H16: 0 | I16: 0 | J16: 0 | K16: 0 | L16: 31.034483 | M16: 780 | N16: 23.333333
A17: Content Marketing | B17: 25000 | C17: 190000 | D17: =IFERROR((C16-B16)/B16,0) | E17: 2200 | F17: 320 | G17: =IFERROR(F16/E16,0) | H17: 0 | I17: 0 | J17: 0 | K17: 0 | L17: 78.125 | M17: 900 | N17: 7.6
A18: Affiliate | B18: 62000 | C18: 245000 | D18: =IFERROR((C17-B17)/B17,0) | E18: 1800 | F18: 290 | G18: =IFERROR(F17/E17,0) | H18: 480000 | I18: 12000 | J18: 0.025 | K18: 5.1666667 | L18: 213.7931 | M18: 580 | N18: 3.9516129
A19: Influencer | B19: 85000 | C19: 310000 | D19: =IFERROR((C18-B18)/B18,0) | E19: 2900 | F19: 380 | G19: =IFERROR(F18/E18,0) | H19: 620000 | I19: 15000 | J19: 0.024193548 | K19: 5.6666667 | L19: 223.68421 | M19: 810 | N19: 3.6470588
A20: YouTube Ads | B20: 72000 | C20: 290000 | D20: =IFERROR((C19-B19)/B19,0) | E20: 2400 | F20: 340 | G20: =IFERROR(F19/E19,0) | H20: 780000 | I20: 19500 | J20: 0.025 | K20: 3.6923077 | L20: 211.76471 | M20: 750 | N20: 4.0277778
A21: Twitter/X Ads | B21: 28000 | C21: 95000 | D21: =IFERROR((C20-B20)/B20,0) | E21: 1100 | F21: 140 | G21: =IFERROR(F20/E20,0) | H21: 520000 | I21: 13000 | J21: 0.025 | K21: 2.1538462 | L21: 200 | M21: 520 | N21: 3.3928571
A22: TikTok Ads | B22: 45000 | C22: 165000 | D22: =IFERROR((C21-B21)/B21,0) | E22: 2200 | F22: 280 | G22: =IFERROR(F21/E21,0) | H22: 980000 | I22: 24500 | J22: 0.025 | K22: 1.8367347 | L22: 160.71429 | M22: 640 | N22: 3.6666667
A23: Display/Banner | B23: 38000 | C23: 125000 | D23: =IFERROR((C22-B22)/B22,0) | E23: 1400 | F23: 175 | G23: =IFERROR(F22/E22,0) | H23: 1450000 | I23: 36200 | J23: 0.024965517 | K23: 1.0497238 | L23: 217.14286 | M23: 490 | N23: 3.2894737
... A25: Webinars | B25: 15000 | C25: 120000 | D25: =IFERROR((C24-B24)/B24,0) | E25: 1200 | F25: 190 | G25: =IFERROR(F24/E24,0) | H25: 0 | I25: 0 | J25: 0 | K25: 0 | L25: 78.947368 | M25: 950 | N25: 8
A26: TOTAL / AVERAGE | B26: =SUM(B11:B24) | C26: =SUM(C11:C24) | E26: =SUM(E11:E24) | F26: =SUM(F11:F24) | H26: =SUM(H11:H24) | I26: =SUM(I11:I24)
A28: MONTHLY BUDGET vs ACTUAL | ALL CHANNELS
A29: Channel | B29: Jan | C29: Feb | D29: Mar | E29: Apr | F29: May | G29: Jun | H29: Jul | I29: Aug | J29: Sep | K29: Oct | L29: Nov | M29: Dec | N29: Total
A30: Google Ads | B30: 15005 | C30: 17041 | D30: 16502 | E30: 16681 | F30: 13849 | G30: 14868 | H30: 13466 | I30: 14645 | J30: 17191 | K30: 15704 | L30: 14660 | M30: 16440 | N30: =SUM(B29:M29)
A31: Facebook Ads | B31: 13239 | C31: 12862 | D31: 11522 | E31: 12048 | F31: 10634 | G31: 11542 | H31: 13586 | I31: 13308 | J31: 13621 | K31: 12979 | L31: 10978 | M31: 12961 | N31: =SUM(B30:M30)
A32: LinkedIn Ads | B32: 8677 | C32: 7264 | D32: 9025 | E32: 9034 | F32: 7614 | G32: 8507 | H32: 8938 | I32: 8064 | J32: 7018 | K32: 8930 | L32: 7849 | M32: 6891 | N32: =SUM(B31:M31)
A33: Email Marketing | B33: 2942 | C33: 3048 | D33: 2668 | E33: 2959 | F33: 3157 | G33: 2695 | H33: 2642 | I33: 2577 | J33: 3153 | K33: 2745 | L33: 2670 | M33: 2659 | N33: =SUM(B32:M32)
A34: SEO/Organic | B34: 1694 | C34: 1621 | D34: 1440 | E34: 1577 | F34: 1447 | G34: 1715 | H34: 1634 | I34: 1586 | J34: 1620 | K34: 1695 | L34: 1695 | M34: 1691 | N34: =SUM(B33:M33)
A35: Content Marketing | B35: 2282 | C35: 2266 | D35: 1858 | E35: 2254 | F35: 1968 | G35: 2269 | H35: 1981 | I35: 1907 | J35: 2213 | K35: 1782 | L35: 2069 | M35: 1777 | N35: =SUM(B34:M34)
A36: Affiliate | B36: 5269 | C36: 5648 | D36: 5302 | E36: 5179 | F36: 5618 | G36: 4303 | H36: 5610 | I36: 4308 | J36: 4617 | K36: 4933 | L36: 4606 | M36: 4684 | N36: =SUM(B35:M35)
A37: Influencer | B37: 6600 | C37: 6370 | D37: 7159 | E37: 7680 | F37: 6796 | G37: 7168 | H37: 6623 | I37: 7558 | J37: 6545 | K37: 6679 | L37: 7728 | M37: 6658 | N37: =SUM(B36:M36)
A38: YouTube Ads | B38: 6732 | C38: 6045 | D38: 5373 | E38: 6085 | F38: 5975 | G38: 6280 | H38: 6129 | I38: 5734 | J38: 6398 | K38: 6002 | L38: 6709 | M38: 5359 | N38: =SUM(B37:M37)
A39: Twitter/X Ads | B39: 2692 | C39: 2507 | D39: 2557 | E39: 2841 | F39: 2422 | G39: 2457 | H39: 2399 | I39: 2725 | J39: 2503 | K39: 2438 | L39: 2786 | M39: 2219 | N39: =SUM(B38:M38)
A40: TikTok Ads | B40: 4288 | C40: 3919 | D40: 4368 | E40: 4170 | F40: 4340 | G40: 3866 | H40: 4096 | I40: 4427 | J40: 3519 | K40: 3669 | L40: 3791 | M40: 3432 | N40: =SUM(B39:M39)
A41: Display/Banner | B41: 2931 | C41: 3178 | D41: 3114 | E41: 3238 | F41: 3144 | G41: 3394 | H41: 3131 | I41: 3384 | J41: 3608 | K41: 2889 | L41: 3023 | M41: 3451 | N41: =SUM(B40:M40)
... A43: Webinars | B43: 1095 | C43: 1153 | D43: 1332 | E43: 1316 | F43: 1143 | G43: 1369 | H43: 1192 | I43: 1357 | J43: 1247 | K43: 1211 | L43: 1355 | M43: 1146 | N43: =SUM(B42:M42)
A44: TOTAL | B44: =SUM(B29:B42) | C44: =SUM(C29:C42) | D44: =SUM(D29:D42) | E44: =SUM(E29:E42) | F44: =SUM(F29:F42) | G44: =SUM(G29:G42) | H44: =SUM(H29:H42) | I44: =SUM(I29:I42) | ... M44: =SUM(M29:M42) | N44: =SUM(B43:M43)
A46: CONVERSION FUNNEL ANALYSIS | By Channel
A47: Channel | B47: Impressions | C47: Clicks | D47: Leads | E47: MQLs | F47: SQLs | G47: Opportunities | H47: Closed Won
A48: Google Ads | B48: 892000 | C48: 22400 | D48: 4200 | E48: 2100 | F48: 840 | G48: 336 | H48: 168
...

Sheet Campaign Data
A1: Campaign ID | B1: Campaign Name | C1: Channel | D1: Type | E1: Quarter | F1: Spend | G1: Revenue | H1: Leads | I1: Conversions | J1: Clicks | K1: Impressions | L1: CTR | M1: CPC | N1: CPA | O1: ROI | P1: Conv Rate | Q1: Start Date | R1: End Date | S1: Target Audience | T1: Status | U1: Notes
A2: CAMP-2025001 | B2: Google Ads - Brand Awareness - Q1 Alpha | C2: Google Ads | D2: Brand Awareness | E2: Q1 | F2: 71000 | G2: 244420 | H2: 1652 | I2: 315 | J2: 24515 | K2: 638316 | L2: =IFERROR(J2/K2,0) | M2: =IFERROR(F2/J2,0) | N2: =IFERROR(F2/I2,0) | O2: =IFERROR((G2-F2)/F2,0) | P2: =IFERROR(I2/H2,0) | Q2: 2025-05-31 | R2: 2025-08-09 | S2: B2B Executives | T2: Completed | U2: Brand Awareness campaign - B2B Executives
A3: CAMP-2025002 | B3: Facebook Ads - Lead Gen - Q1 Beta | C3: Facebook Ads | D3: Lead Gen | E3: Q1 | F3: 70000 | G3: 130427 | H3: 2131 | I3: 395 | J3: 25469 | K3: 1235764 | L3: =IFERROR(J3/K3,0) | M3: =IFERROR(F3/J3,0) | N3: =IFERROR(F3/I3,0) | O3: =IFERROR((G3-F3)/F3,0) | P3: =IFERROR(I3/H3,0) | Q3: 2025-02-06 | R3: 2025-05-07 | S3: SMB Owners | T3: Completed | U3: Lead Gen campaign - SMB Owners
A4: CAMP-2025003 | B4: LinkedIn Ads - Retargeting - Q1 Gamma | C4: LinkedIn Ads | D4: Retargeting | E4: Q1 | F4: 47000 | G4: 70564 | H4: 2215 | I4: 332 | J4: 55514 | K4: 848443 | L4: =IFERROR(J4/K4,0) | M4: =IFERROR(F4/J4,0) | N4: =IFERROR(F4/I4,0) | O4: =IFERROR((G4-F4)/F4,0) | P4: =IFERROR(I4/H4,0) | Q4: 2025-08-19 | R4: 2025-09-22 | S4: Enterprise IT | T4: Completed | U4: Retargeting campaign - Enterprise IT
A5: CAMP-2025004 | B5: Email Marketing - Product Launch - Q2 Delta | C5: Email Marketing | D5: Product Launch | E5: Q2 | F5: 32000 | G5: 138198 | H5: 1194 | I5: 109 | J5: 0 | K5: 0 | L5: =IFERROR(J5/K5,0) | M5: =IFERROR(F5/J5,0) | N5: =IFERROR(F5/I5,0) | O5: =IFERROR((G5-F5)/F5,0) | P5: =IFERROR(I5/H5,0) | Q5: 2025-01-01 | R5: 2025-01-19 | S5: Marketing Leaders | T5: Completed | U5: Product Launch campaign - Marketing Leaders
A6: CAMP-2025005 | B6: SEO/Organic - Nurture - Q2 Epsilon | C6: SEO/Organic | D6: Nurture | E6: Q2 | F6: 48000 | G6: 120286 | H6: 1464 | I6: 261 | J6: 0 | K6: 0 | L6: =IFERROR(J6/K6,0) | M6: =IFERROR(F6/J6,0) | N6: =IFERROR(F6/I6,0) | O6: =IFERROR((G6-F6)/F6,0) | P6: =IFERROR(I6/H6,0) | Q6: 2025-03-29 | R6: 2025-05-17 | S6: Finance Teams | T6: Active | U6: Nurture campaign - Finance Teams
A7: CAMP-2025006 | B7: Content Marketing - Event Promo - Q2 Alpha | C7: Content Marketing | D7: Event Promo | E7: Q2 | F7: 19000 | G7: 30238 | H7: 937 | I7: 159 | J7: 0 | K7: 0 | L7: =IFERROR(J7/K7,0) | M7: =IFERROR(F7/J7,0) | N7: =IFERROR(F7/I7,0) | O7: =IFERROR((G7-F7)/F7,0) | P7: =IFERROR(I7/H7,0) | Q7: 2025-02-04 | R7: 2025-02-23 | S7: E-commerce | T7: Completed | U7: Event Promo campaign - E-commerce
A8: CAMP-2025007 | B8: Affiliate - Seasonal - Q3 Beta | C8: Affiliate | D8: Seasonal | E8: Q3 | F8: 6000 | G8: 17633 | H8: 138 | I8: 16 | J8: 5101 | K8: 91466 | L8: =IFERROR(J8/K8,0) | M8: =IFERROR(F8/J8,0) | N8: =IFERROR(F8/I8,0) | O8: =IFERROR((G8-F8)/F8,0) | P8: =IFERROR(I8/H8,0) | Q8: 2025-12-02 | R8: 2026-02-12 | S8: Tech Startups | T8: Active | U8: Seasonal campaign - Tech Startups
A9: CAMP-2025008 | B9: Influencer - Upsell - Q3 Gamma | C9: Influencer | D9: Upsell | E9: Q3 | F9: 48000 | G9: 159876 | H9: 1059 | I9: 147 | J9: 29899 | K9: 1175421 | L9: =IFERROR(J9/K9,0) | M9: =IFERROR(F9/J9,0) | N9: =IFERROR(F9/I9,0) | O9: =IFERROR((G9-F9)/F9,0) | P9: =IFERROR(I9/H9,0) | Q9: 2025-05-22 | R9: 2025-08-10 | S9: Healthcare | T9: Active | U9: Upsell campaign - Healthcare
A10: CAMP-2025009 | B10: YouTube Ads - Cross-sell - Q3 Delta | C10: YouTube Ads | D10: Cross-sell | E10: Q3 | F10: 23000 | G10: 47424 | H10: 387 | I10: 80 | J10: 7804 | K10: 180975 | L10: =IFERROR(J10/K10,0) | M10: =IFERROR(F10/J10,0) | N10: =IFERROR(F10/I10,0) | O10: =IFERROR((G10-F10)/F10,0) | P10: =IFERROR(I10/H10,0) | Q10: 2025-06-08 | R10: 2025-06-28 | S10: Retail | T10: Completed | U10: Cross-sell campaign - Retail
A11: CAMP-2025010 | B11: Twitter/X Ads - Winback - Q4 Epsilon | C11: Twitter/X Ads | D11: Winback | E11: Q4 | F11: 50000 | G11: 90481 | H11: 1771 | I11: 279 | J11: 15138 | K11: 246302 | L11: =IFERROR(J11/K11,0) | M11: =IFERROR(F11/J11,0) | N11: =IFERROR(F11/I11,0) | O11: =IFERROR((G11-F11)/F11,0) | P11: =IFERROR(I11/H11,0) | Q11: 2025-04-24 | R11: 2025-06-21 | S11: SaaS Companies | T11: Planning | U11: Winback campaign - SaaS Companies
A12: CAMP-2025011 | B12: TikTok Ads - Brand Awareness - Q4 Alpha | C12: TikTok Ads | D12: Brand Awareness | E12: Q4 | F12: 51000 | G12: 141986 | H12: 1007 | I12: 82 | J12: 47520 | K12: 738671 | L12: =IFERROR(J12/K12,0) | M12: =IFERROR(F12/J12,0) | N12: =IFERROR(F12/I12,0) | O12: =IFERROR((G12-F12)/F12,0) | P12: =IFERROR(I12/H12,0) | Q12: 2025-02-13 | R12: 2025-05-10 | S12: B2B Executives | T12: Completed | U12: Brand Awareness campaign - B2B Executives
A13: CAMP-2025012 | B13: Display/Banner - Lead Gen - Q4 Beta | C13: Display/Banner | D13: Lead Gen | E13: Q4 | F13: 64000 | G13: 199273 | H13: 1462 | I13: 171 | J13: 24576 | K13: 345683 | L13: =IFERROR(J13/K13,0) | M13: =IFERROR(F13/J13,0) | N13: =IFERROR(F13/I13,0) | O13: =IFERROR((G13-F13)/F13,0) | P13: =IFERROR(I13/H13,0) | Q13: 2025-11-03 | R13: 2026-01-04 | S13: SMB Owners | T13: Planning | U13: Lead Gen campaign - SMB Owners
... A201: CAMP-2025200 | B201: Email Marketing - Winback - Q3 Epsilon | C201: Email Marketing | D201: Winback | E201: Q3 | F201: 12000 | G201: 24425 | H201: 788 | I201: 126 | J201: 0 | K201: 0 | L201: =IFERROR(J201/K201,0) | M201: =IFERROR(F201/J201,0) | N201: =IFERROR(F201/I201,0) | O201: =IFERROR((G201-F201)/F201,0) | P201: =IFERROR(I201/H201,0) | Q201: 2025-05-20 | R201: 2025-07-11 | S201: SaaS Companies | T201: Completed | U201: Winback campaign - SaaS Companies

Sheet SEO & Organic
A1: SEO & ORGANIC PERFORMANCE | Keyword & Page Analytics
A2: Keyword / Page | B2: Category | C2: Monthly Searches | D2: Rank | E2: Prev Rank | F2: Rank Change | G2: Organic Clicks | H2: CTR | I2: Bounce Rate | J2: Avg Time | K2: Conversions | L2: Revenue Value
A3: marketing automation software | B3: PPC | C3: 800 | D3: 14 | E3: 7 | F3: =E3-D3 | G3: 8 | H3: 0.01 | I3: 0.44338619 | J3: 2.8 | K3: 0 | L3: 0
A4: CRM for small business | B4: CRM | C4: 3000 | D4: 20 | E4: 20 | F4: =E4-D4 | G4: 30 | H4: 0.01 | I4: 0.49346382 | J4: 5.6 | K4: 2 | L4: 2452
A5: email marketing tools | B5: Email | C5: 15000 | D5: 29 | E5: 37 | F5: =E5-D5 | G5: 150 | H5: 0.01 | I5: 0.4811282 | J5: 5.7 | K5: 9 | L5: 5985
A6: social media management | B6: Social | C6: 8000 | D6: 43 | E6: 42 | F6: =E6-D6 | G6: 80 | H6: 0.01 | I6: 0.44147627 | J6: 5.3 | K6: 5 | L6: 5985
A7: SEO audit tool | B7: SEO | C7: 3000 | D7: 16 | E7: 23 | F7: =E7-D7 | G7: 30 | H7: 0.01 | I7: 0.72092656 | J7: 2.7 | K7: 2 | L7: 1390
A8: content marketing strategy | B8: Content | C8: 5000 | D8: 28 | E8: 23 | F8: =E8-D8 | G8: 50 | H8: 0.01 | I8: 0.50913193 | J8: 3.7 | K8: 4 | L8: 4468
A9: digital marketing agency | B9: Agency | C9: 8000 | D9: 37 | E9: 43 | F9: =E9-D9 | G9: 80 | H9: 0.01 | I9: 0.3835211 | J9: 1.7 | K9: 6 | L9: 1476
A10: PPC management software | B10: PPC | C10: 1000 | D10: 17 | E10: 10 | F10: =E10-D10 | G10: 10 | H10: 0.01 | I10: 0.42536326 | J10: 3.5 | K10: 0 | L10: 0
A11: lead generation platform | B11: Lead Gen | C11: 1500 | D11: 38 | E11: 43 | F11: =E11-D11 | G11: 15 | H11: 0.01 | I11: 0.53183134 | J11: 1.4 | K11: 0 | L11: 0
A12: marketing analytics dashboard | B12: Analytics | C12: 500 | D12: 50 | E12: 51 | F12: =E12-D12 | G12: 5 | H12: 0.01 | I12: 0.64348408 | J12: 4.8 | K12: 0 | L12: 0
A13: customer data platform | B13: Data | C13: 800 | D13: 8 | E13: 3 | F13: =E13-D13 | G13: 10 | H13: 0.0125 | I13: 0.41299868 | J13: 4.1 | K13: 0 | L13: 0
A14: ABM marketing tools | B14: ABM | C14: 500 | D14: 27 | E14: 29 | F14: =E14-D14 | G14: 5 | H14: 0.01 | I14: 0.51619406 | J14: 4.3 | K14: 0 | L14: 0
... A52: churn reduction | B52: Retention | C52: 2000 | D52: 28 | E52: 22 | F52: =E52-D52 | G52: 20 | H52: 0.01 | I52: 0.43809652 | J52: 2.3 | K52: 0 | L52: 0

Sheet Email Performance
A1: EMAIL MARKETING PERFORMANCE | Campaign-Level Analysis
A2: Campaign Name | B2: Type | C2: Send Date | D2: List Size | E2: Delivered | F2: Open Rate | G2: Click Rate | H2: Bounce Rate | I2: Unsubscribes | J2: Conversions | K2: Revenue | L2: Cost
A3: Monthly Newsletter | B3: Newsletter | C3: 2025-01-01 | D3: 31343 | E3: 30217 | F3: 0.17831382 | G3: 0.038444424 | H3: 0.036 | I3: 67 | J3: 33 | K3: 7458 | L3: 820
A4: Summer Sale Promo | B4: Promotional | C4: 2025-01-13 | D4: 46043 | E4: 44840 | F4: 0.20236916 | G4: 0.10196828 | H4: 0.026 | I4: 58 | J4: 120 | K4: 41520 | L4: 702
A5: Welcome Series #1 | B5: Drip - Welcome | C5: 2025-01-25 | D5: 30398 | E5: 29678 | F5: 0.15679892 | G5: 0.028042408 | H5: 0.024 | I5: 118 | J5: 20 | K5: 8340 | L5: 838
A6: Lead Nurture Wk2 | B6: Drip - Nurture | C6: 2025-02-06 | D6: 28162 | E6: 27543 | F6: 0.17805156 | G6: 0.027908792 | H6: 0.022 | I6: 137 | J6: 26 | K6: 18252 | L6: 541
A7: Win-Back Inactive | B7: Re-engagement | C7: 2025-02-18 | D7: 23386 | E7: 22890 | F7: 0.31908032 | G7: 0.060555302 | H7: 0.021 | I7: 87 | J7: 39 | K7: 18798 | L7: 626
A8: New Feature Release | B8: Product Update | C8: 2025-03-02 | D8: 30305 | E8: 28934 | F8: 0.32057205 | G8: 0.093991767 | H8: 0.045 | I8: 58 | J8: 144 | K8: 100944 | L8: 888
A9: Webinar Invitation | B9: Event Invite | C9: 2025-03-14 | D9: 21506 | E9: 21184 | F9: 0.33132559 | G9: 0.10955615 | H9: 0.015 | I9: 101 | J9: 112 | K9: 45248 | L9: 603
A10: Upgrade to Pro | B10: Upsell | C10: 2025-03-26 | D10: 43153 | E10: 42337 | F10: 0.41046567 | G10: 0.031419978 | H10: 0.019 | I10: 56 | J10: 93 | K10: 20367 | L10: 1034
A11: 30-Day Winback | B11: Winback | C11: 2025-04-07 | D11: 31419 | E11: 30585 | F11: 0.15667373 | G11: 0.020033405 | H11: 0.027 | I11: 83 | J11: 19 | K11: 3743 | L11: 1161
A12: Order Confirmation | B12: Transactional | C12: 2025-04-19 | D12: 5844 | E12: 5770 | F12: 0.32652867 | G12: 0.10210393 | H12: 0.013 | I12: 26 | J12: 32 | K12: 14624 | L12: 970
A13: Weekly Digest | B13: Newsletter | C13: 2025-05-01 | D13: 6791 | E13: 6571 | F13: 0.16141849 | G13: 0.1091949 | H13: 0.032 | I13: 7 | J13: 23 | K13: 17043 | L13: 746
A14: Black Friday Offer | B14: Promotional | C14: 2025-05-13 | D14: 25253 | E14: 24954 | F14: 0.38006028 | G14: 0.061654634 | H14: 0.012 | I14: 31 | J14: 113 | K14: 50737 | L14: 1065
... A32: Account Health Check | B32: Transactional | C32: 2025-12-15 | D32: 17307 | E32: 16772 | F32: 0.34739336 | G32: 0.082649828 | H32: 0.031 | I32: 40 | J32: 68 | K32: 12920 | L32: 832

Sheet ⚙️ Settings
A1: MARKETING DASHBOARD SETTINGS & BENCHMARKS
A3: Setting | B3: Value | C3: Description
A4: Annual Marketing Budget | B4: 871000 | C4: Total FY2025 marketing spend
A5: Revenue Target | B5: 3500000 | C5: Total revenue target from marketing
A6: Target Overall ROI | B6: 3 | C6: 3x return on marketing spend
A7: Target CPA | B7: 85 | C7: Target cost per acquisition
A8: Target Conv Rate | B8: 0.08 | C8: 8% lead-to-customer conversion
A9: Target Email Open Rate | B9: 0.25 | C9: 25% benchmark open rate
A10: Target Email CTR | B10: 0.04 | C10: 4% benchmark click-through rate
A11: Target Organic Traffic Growth | B11: 0.15 | C11: 15% YoY organic growth
A12: Avg Customer LTV | B12: 750 | C12: Lifetime value assumption
A13: CAC Payback Period (months) | B13: 12 | C13: Months to recover acquisition cost
A14: Target ROAS (Paid) | B14: 3.5 | C14: Return on ad spend target
A15: Brand Awareness Budget % | B15: 0.2 | C15: Share of budget for brand
