Workbook

Sheet 📊 Dashboard
A1: SALES PERFORMANCE TRACKER | FY 2026
A3: Farhan Siddique | Virtual Assistant & Data Specialist | May 2026
A4: Executive Summary | All figures in USD | Data auto-updates from 'Data' sheet
B6: Total Revenue | D6: Units Sold | F6: Avg Deal Size | H6: Target Achievement | J6: YoY Growth | L6: Active Reps | N6: Win Rate | P6: Avg Sales Cycle (days)
B7: =SUM(Data!H2:H501) | D7: =SUM(Data!G2:G501) | F7: =IFERROR(SUM(Data!H2:H501)/COUNTIF(Data!H2:H501,">0"),0) | H7: =IFERROR(SUM(Data!H2:H501)/SUM(Data!I2:I501),0) | J7: =IFERROR((SUM(Data!H2:H501)-SUM(Data!J2:J501))/SUM(Data!J2:J501),0) | L7: =COUNTA(Data!C2:C501)-SUMPRODUCT((1/COUNTIF(Data!C2:C501,Data!C2:C501)))-1+1 | N7: =IFERROR(COUNTIF(Data!K2:K501,"Won")/COUNTIF(Data!K2:K501,"<>"),0) | P7: =IFERROR(AVERAGE(Data!L2:L501),0)
A10: MONTHLY REVENUE BY REGION
A11: Region | B11: Jan | C11: Feb | D11: Mar | E11: Apr | F11: May | G11: Jun | H11: Jul | I11: Aug | J11: Sep | K11: Oct | L11: Nov | M11: Dec | N11: Total
A12: North | B12: 461666 | C12: 410523 | D12: 417714 | E12: 512940 | F12: 527041 | G12: 516072 | H12: 502263 | I12: 438734 | J12: 426183 | K12: 575978 | L12: 523969 | M12: 575009 | N12: =SUM(B11:M11)
A13: South | B13: 293297 | C13: 316349 | D13: 285146 | E13: 374826 | F13: 343546 | G13: 363442 | H13: 360031 | I13: 391367 | J13: 387520 | K13: 317963 | L13: 404414 | M13: 345652 | N13: =SUM(B12:M12)
A14: East | B14: 583614 | C14: 525239 | D14: 434342 | E14: 588953 | F14: 506000 | G14: 602212 | H14: 642540 | I14: 496761 | J14: 582716 | K14: 625405 | L14: 664059 | M14: 562373 | N14: =SUM(B13:M13)
A15: West | B15: 257593 | C15: 256351 | D15: 279900 | E15: 305990 | F15: 306628 | G15: 268777 | H15: 299427 | I15: 274571 | J15: 344208 | K15: 351891 | L15: 324401 | M15: 335324 | N15: =SUM(B14:M14)
A16: Central | B16: 213218 | C16: 217160 | D16: 183979 | E16: 213710 | F16: 182281 | G16: 229148 | H16: 228431 | I16: 224470 | J16: 194057 | K16: 190624 | L16: 244934 | M16: 239364 | N16: =SUM(B15:M15)
A17: International | B17: 374806 | C17: 429415 | D17: 371845 | E17: 379778 | F17: 344595 | G17: 431431 | H17: 419492 | I17: 384408 | J17: 379163 | K17: 476081 | L17: 415381 | M17: 422674 | N17: =SUM(B16:M16)
A18: TOTAL | B18: =SUM(B11:B16) | C18: =SUM(C11:C16) | D18: =SUM(D11:D16) | E18: =SUM(E11:E16) | F18: =SUM(F11:F16) | G18: =SUM(G11:G16) | H18: =SUM(H11:H16) | I18: =SUM(I11:I16) | ... M18: =SUM(M11:M16) | N18: =SUM(B17:M17)
A20: PRODUCT PERFORMANCE SUMMARY
A21: Product | B21: Units Sold | C21: Revenue | D21: Target | E21: Achievement | F21: Avg Price | G21: Margin% | H21: Rank | I21: QoQ Growth | J21: Status
A22: Product A | B22: 1850 | C22: 925000 | D22: 900000 | E22: =C21/D21 | F22: =IFERROR(C21/B21,0) | G22: 0.33 | H22: =RANK(C21,C21:C30,0) | I22: 0.020602565 | J22: =IF(E21>=1,"✅ On Track",IF(E21>=0.85,"⚠️ At Risk","❌ Behind"))
A23: Product B | B23: 1420 | C23: 710000 | D23: 750000 | E23: =C22/D22 | F23: =IFERROR(C22/B22,0) | G23: 0.26 | H23: =RANK(C22,C21:C30,0) | I23: 0.094411946 | J23: =IF(E22>=1,"✅ On Track",IF(E22>=0.85,"⚠️ At Risk","❌ Behind"))
A24: Product C | B24: 2100 | C24: 1050000 | D24: 1000000 | E24: =C23/D23 | F24: =IFERROR(C23/B23,0) | G24: 0.38 | H24: =RANK(C23,C21:C30,0) | I24: -0.0097436214 | J24: =IF(E23>=1,"✅ On Track",IF(E23>=0.85,"⚠️ At Risk","❌ Behind"))
A25: Product D | B25: 980 | C25: 490000 | D25: 500000 | E25: =C24/D24 | F25: =IFERROR(C24/B24,0) | G25: 0.18 | H25: =RANK(C24,C21:C30,0) | I25: 0.016848286 | J25: =IF(E24>=1,"✅ On Track",IF(E24>=0.85,"⚠️ At Risk","❌ Behind"))
A26: Product E | B26: 1670 | C26: 835000 | D26: 800000 | E26: =C25/D25 | F26: =IFERROR(C25/B25,0) | G26: 0.31 | H26: =RANK(C25,C21:C30,0) | I26: 0.042736473 | J26: =IF(E25>=1,"✅ On Track",IF(E25>=0.85,"⚠️ At Risk","❌ Behind"))
A27: Product F | B27: 760 | C27: 380000 | D27: 400000 | E27: =C26/D26 | F27: =IFERROR(C26/B26,0) | G27: 0.14 | H27: =RANK(C26,C21:C30,0) | I27: 0.060287817 | J27: =IF(E26>=1,"✅ On Track",IF(E26>=0.85,"⚠️ At Risk","❌ Behind"))
A28: Product G | B28: 2350 | C28: 1175000 | D28: 1100000 | E28: =C27/D27 | F28: =IFERROR(C27/B27,0) | G28: 0.43 | H28: =RANK(C27,C21:C30,0) | I28: 0.10879577 | J28: =IF(E27>=1,"✅ On Track",IF(E27>=0.85,"⚠️ At Risk","❌ Behind"))
A29: Product H | B29: 590 | C29: 295000 | D29: 300000 | E29: =C28/D28 | F29: =IFERROR(C28/B28,0) | G29: 0.11 | H29: =RANK(C28,C21:C30,0) | I29: 0.07310136 | J29: =IF(E28>=1,"✅ On Track",IF(E28>=0.85,"⚠️ At Risk","❌ Behind"))
A30: Product I | B30: 1120 | C30: 560000 | D30: 550000 | E30: =C29/D29 | F30: =IFERROR(C29/B29,0) | G30: 0.2 | H30: =RANK(C29,C21:C30,0) | I30: 0.086758252 | J30: =IF(E29>=1,"✅ On Track",IF(E29>=0.85,"⚠️ At Risk","❌ Behind"))
A31: Product J | B31: 1380 | C31: 690000 | D31: 700000 | E31: =C30/D30 | F31: =IFERROR(C30/B30,0) | G31: 0.25 | H31: =RANK(C30,C21:C30,0) | I31: 0.065912489 | J31: =IF(E30>=1,"✅ On Track",IF(E30>=0.85,"⚠️ At Risk","❌ Behind"))
A34: TOP SALES REP LEADERBOARD
A35: Rank | B35: Rep Name | C35: Region | D35: Q1 Rev | E35: Q2 Rev | F35: Q3 Rev | G35: Q4 Rev | H35: Total | I35: vs Quota
A36: 1 | B36: Sarah Johnson | C36: North | D36: 210000 | E36: 235000 | F36: 198000 | G36: 252000 | H36: 900000 | I36: =IFERROR((H35-850000)/850000,0)
A37: 2 | B37: Mike Chen | C37: West | D37: 195000 | E37: 220000 | F37: 215000 | G37: 240000 | H37: 870000 | I37: =IFERROR((H36-820000)/820000,0)
A38: 3 | B38: Priya Sharma | C38: East | D38: 185000 | E38: 198000 | F38: 210000 | G38: 228000 | H38: 821000 | I38: =IFERROR((H37-780000)/780000,0)
A39: 4 | B39: James Williams | C39: South | D39: 175000 | E39: 190000 | F39: 200000 | G39: 220000 | H39: 785000 | I39: =IFERROR((H38-740000)/740000,0)
A40: 5 | B40: Emily Davis | C40: Central | D40: 165000 | E40: 180000 | F40: 195000 | G40: 210000 | H40: 750000 | I40: =IFERROR((H39-700000)/700000,0)
A41: 6 | B41: Carlos Ruiz | C41: International | D41: 160000 | E41: 175000 | F41: 188000 | G41: 202000 | H41: 725000 | I41: =IFERROR((H40-680000)/680000,0)
A42: 7 | B42: Lisa Park | C42: North | D42: 150000 | E42: 168000 | F42: 180000 | G42: 195000 | H42: 693000 | I42: =IFERROR((H41-650000)/650000,0)
A43: 8 | B43: Tom Brown | C43: West | D43: 142000 | E43: 158000 | F43: 172000 | G43: 188000 | H43: 660000 | I43: =IFERROR((H42-620000)/620000,0)
A44: 9 | B44: Anna Schmidt | C44: East | D44: 135000 | E44: 150000 | F44: 165000 | G44: 180000 | H44: 630000 | I44: =IFERROR((H43-590000)/590000,0)
A45: 10 | B45: David Kim | C45: South | D45: 128000 | E45: 142000 | F45: 158000 | G45: 172000 | H45: 600000 | I45: =IFERROR((H44-560000)/560000,0)
A46: 11 | B46: Rachel Green | C46: Central | D46: 120000 | E46: 135000 | F46: 150000 | G46: 165000 | H46: 570000 | I46: =IFERROR((H45-530000)/530000,0)
A47: 12 | B47: Mark Thompson | C47: International | D47: 112000 | E47: 128000 | F47: 142000 | G47: 158000 | H47: 540000 | I47: =IFERROR((H46-500000)/500000,0)
...

Sheet Data
A1: Date | B1: Month | C1: Rep Name | D1: Region | E1: Product | F1: Category | G1: Units Sold | H1: Revenue | I1: Target | J1: Prev Year Rev | K1: Status | L1: Sales Cycle (days) | M1: Customer Name | N1: Deal Size | O1: Lead Source | P1: Commission | Q1: Discount% | R1: Notes
A2: 2025-04-25 | B2: April | C2: Sarah Johnson | D2: North | E2: Product A | F2: Enterprise | G2: 29 | H2: 1449971 | I2: 1719855 | J2: 1251530 | K2: Won | L2: 34 | M2: Acme Corp | N2: Enterprise (>$200K) | O2: Referral | P2: =H2*0.08 | Q2: 0.14 | R2: Q1 deal - Referral channel
A3: 2025-12-17 | B3: December | C3: Mike Chen | D3: West | E3: Product B | F3: SMB | G3: 8 | H3: 39992 | I3: 45301 | J3: 34174 | K3: Won | L3: 99 | M3: Beta Inc | N3: Medium ($10K-$50K) | O3: Cold Call | P3: =H3*0.08 | Q3: 0.04 | R3: Q2 deal - Cold Call channel
A4: 2025-08-28 | B4: August | C4: Priya Sharma | D4: East | E4: Product C | F4: Mid-Market | G4: 16 | H4: 399984 | I4: 383802 | J4: 385995 | K4: Won | L4: 103 | M4: Gamma LLC | N4: Enterprise (>$200K) | O4: LinkedIn | P4: =H4*0.08 | Q4: 0.01 | R4: Q3 deal - LinkedIn channel
A5: 2025-02-16 | B5: February | C5: James Williams | D5: South | E5: Product D | F5: Startup | G5: 15 | H5: 374985 | I5: 344961 | J5: 334562 | K5: Lost | L5: 102 | M5: Delta Ltd | N5: Enterprise (>$200K) | O5: Trade Show | P5: =H5*0.08 | Q5: 0.07 | R5: Q4 deal - Trade Show channel
A6: 2025-12-29 | B6: December | C6: Emily Davis | D6: Central | E6: Product E | F6: Government | G6: 48 | H6: 1199952 | I6: 1392336 | J6: 1146351 | K6: In Progress | L6: 104 | M6: Epsilon Co | N6: Enterprise (>$200K) | O6: Website | P6: =H6*0.08 | Q6: 0.07 | R6: Q1 deal - Website channel
A7: 2025-07-06 | B7: July | C7: Carlos Ruiz | D7: International | E7: Product F | F7: Enterprise | G7: 28 | H7: 279972 | I7: 303870 | J7: 273570 | K7: In Progress | L7: 110 | M7: Zeta Corp | N7: Enterprise (>$200K) | O7: Partner | P7: =H7*0.08 | Q7: 0.12 | R7: Q2 deal - Partner channel
A8: 2025-03-01 | B8: March | C8: Lisa Park | D8: North | E8: Product G | F8: SMB | G8: 38 | H8: 189962 | I8: 187317 | J8: 184726 | K8: Won | L8: 9 | M8: Eta Inc | N8: Large ($50K-$200K) | O8: Email Campaign | P8: =H8*0.08 | Q8: 0.02 | R8: Q3 deal - Email Campaign channel
A9: 2025-11-19 | B9: November | C9: Tom Brown | D9: West | E9: Product H | F9: Mid-Market | G9: 25 | H9: 249975 | I9: 284941 | J9: 254019 | K9: Won | L9: 78 | M9: Theta LLC | N9: Enterprise (>$200K) | O9: Webinar | P9: =H9*0.08 | Q9: 0.01 | R9: Q4 deal - Webinar channel
A10: 2025-05-20 | B10: May | C10: Anna Schmidt | D10: East | E10: Product I | F10: Startup | G10: 11 | H10: 164989 | I10: 174433 | J10: 150315 | K10: Won | L10: 83 | M10: Iota Ltd | N10: Large ($50K-$200K) | O10: SEO | P10: =H10*0.08 | Q10: 0.12 | R10: Q1 deal - SEO channel
A11: 2025-08-03 | B11: August | C11: David Kim | D11: South | E11: Product J | F11: Government | G11: 43 | H11: 2149957 | I11: 2571777 | J11: 2100832 | K11: Won | L11: 84 | M11: Kappa Co | N11: Enterprise (>$200K) | O11: Direct | P11: =H11*0.08 | Q11: 0.1 | R11: Q2 deal - Direct channel
A12: 2025-02-25 | B12: February | C12: Rachel Green | D12: Central | E12: Product A | F12: Enterprise | G12: 7 | H12: 139993 | I12: 139324 | J12: 152111 | K12: Lost | L12: 28 | M12: Lambda Corp | N12: Large ($50K-$200K) | O12: Referral | P12: =H12*0.08 | Q12: 0.03 | R12: Q3 deal - Referral channel
A13: 2025-06-22 | B13: June | C13: Mark Thompson | D13: International | E13: Product B | F13: SMB | G13: 32 | H13: 159968 | I13: 190340 | J13: 140777 | K13: In Progress | L13: 37 | M13: Mu Inc | N13: Large ($50K-$200K) | O13: Cold Call | P13: =H13*0.08 | Q13: 0.14 | R13: Q4 deal - Cold Call channel
... A501: 2025-06-11 | B501: June | C501: Daniel Jackson | D501: West | E501: Product J | F501: Government | G501: 15 | H501: 449985 | I501: 417953 | J501: 388038 | K501: Won | L501: 64 | M501: Phi Co | N501: Enterprise (>$200K) | O501: Direct | P501: =H501*0.08 | Q501: 0.15 | R501: Q4 deal - Direct channel

Sheet Monthly Analysis
A1: MONTHLY REVENUE ANALYSIS | FY 2025
A2: Month | B2: North | C2: South | D2: East | E2: West | F2: Central | G2: International | H2: Total | I2: MoM Change | J2: vs Budget | K2: Budget | L2: Cum Revenue | M2: Run Rate | N2: Full Year Fcst
A3: Jan | B3: 476647 | C3: 308779 | D3: 549296 | E3: 265037 | F3: 185509 | G3: 355419 | H3: =SUM(B3:G3) | I3: N/A | J3: =IFERROR((H3-K3)/K3,0) | K3: 920000 | L3: =SUM($H$3:H3) | M3: =IFERROR(L3/1*12,0) | N3: =IFERROR(L3+((920000)*(11)),0)
A4: Feb | B4: 442173 | C4: 296867 | D4: 558615 | E4: 256325 | F4: 199377 | G4: 394982 | H4: =SUM(B4:G4) | I4: =IFERROR((H4-H3)/H3,0) | J4: =IFERROR((H4-K4)/K4,0) | K4: 940000 | L4: =SUM($H$3:H4) | M4: =IFERROR(L4/2*12,0) | N4: =IFERROR(L4+((940000)*(10)),0)
A5: Mar | B5: 422428 | C5: 299948 | D5: 499007 | E5: 298299 | F5: 178164 | G5: 385966 | H5: =SUM(B5:G5) | I5: =IFERROR((H5-H4)/H4,0) | J5: =IFERROR((H5-K5)/K5,0) | K5: 980000 | L5: =SUM($H$3:H5) | M5: =IFERROR(L5/3*12,0) | N5: =IFERROR(L5+((980000)*(9)),0)
A6: Apr | B6: 504188 | C6: 305101 | D6: 508805 | E6: 319899 | F6: 185352 | G6: 401292 | H6: =SUM(B6:G6) | I6: =IFERROR((H6-H5)/H5,0) | J6: =IFERROR((H6-K6)/K6,0) | K6: 1050000 | L6: =SUM($H$3:H6) | M6: =IFERROR(L6/4*12,0) | N6: =IFERROR(L6+((1050000)*(8)),0)
A7: May | B7: 488671 | C7: 303338 | D7: 530330 | E7: 306118 | F7: 195877 | G7: 387191 | H7: =SUM(B7:G7) | I7: =IFERROR((H7-H6)/H6,0) | J7: =IFERROR((H7-K7)/K7,0) | K7: 1100000 | L7: =SUM($H$3:H7) | M7: =IFERROR(L7/5*12,0) | N7: =IFERROR(L7+((1100000)*(7)),0)
A8: Jun | B8: 505549 | C8: 358793 | D8: 588771 | E8: 313075 | F8: 202486 | G8: 437377 | H8: =SUM(B8:G8) | I8: =IFERROR((H8-H7)/H7,0) | J8: =IFERROR((H8-K8)/K8,0) | K8: 1150000 | L8: =SUM($H$3:H8) | M8: =IFERROR(L8/6*12,0) | N8: =IFERROR(L8+((1150000)*(6)),0)
A9: Jul | B9: 455447 | C9: 367003 | D9: 548397 | E9: 308280 | F9: 214070 | G9: 424824 | H9: =SUM(B9:G9) | I9: =IFERROR((H9-H8)/H8,0) | J9: =IFERROR((H9-K9)/K9,0) | K9: 1120000 | L9: =SUM($H$3:H9) | M9: =IFERROR(L9/7*12,0) | N9: =IFERROR(L9+((1120000)*(5)),0)
A10: Aug | B10: 514925 | C10: 341776 | D10: 548305 | E10: 328116 | F10: 193576 | G10: 392783 | H10: =SUM(B10:G10) | I10: =IFERROR((H10-H9)/H9,0) | J10: =IFERROR((H10-K10)/K10,0) | K10: 1090000 | L10: =SUM($H$3:H10) | M10: =IFERROR(L10/8*12,0) | N10: =IFERROR(L10+((1090000)*(4)),0)
A11: Sep | B11: 472143 | C11: 349080 | D11: 516584 | E11: 281711 | F11: 218516 | G11: 401087 | H11: =SUM(B11:G11) | I11: =IFERROR((H11-H10)/H10,0) | J11: =IFERROR((H11-K11)/K11,0) | K11: 1060000 | L11: =SUM($H$3:H11) | M11: =IFERROR(L11/9*12,0) | N11: =IFERROR(L11+((1060000)*(3)),0)
A12: Oct | B12: 566714 | C12: 337097 | D12: 606082 | E12: 333135 | F12: 205315 | G12: 449959 | H12: =SUM(B12:G12) | I12: =IFERROR((H12-H11)/H11,0) | J12: =IFERROR((H12-K12)/K12,0) | K12: 1030000 | L12: =SUM($H$3:H12) | M12: =IFERROR(L12/10*12,0) | N12: =IFERROR(L12+((1030000)*(2)),0)
A13: Nov | B13: 524799 | C13: 342145 | D13: 617075 | E13: 343139 | F13: 213025 | G13: 440902 | H13: =SUM(B13:G13) | I13: =IFERROR((H13-H12)/H12,0) | J13: =IFERROR((H13-K13)/K13,0) | K13: 1000000 | L13: =SUM($H$3:H13) | M13: =IFERROR(L13/11*12,0) | N13: =IFERROR(L13+((1000000)*(1)),0)
A14: Dec | B14: 489059 | C14: 361774 | D14: 554266 | E14: 336096 | F14: 217998 | G14: 425521 | H14: =SUM(B14:G14) | I14: =IFERROR((H14-H13)/H13,0) | J14: =IFERROR((H14-K14)/K14,0) | K14: 980000 | L14: =SUM($H$3:H14) | M14: =IFERROR(L14/12*12,0) | N14: =IFERROR(L14+((980000)*(0)),0)
A15: FULL YEAR | B15: =SUM(B3:B14) | C15: =SUM(C3:C14) | D15: =SUM(D3:D14) | E15: =SUM(E3:E14) | F15: =SUM(F3:F14) | G15: =SUM(G3:G14) | H15: =SUM(H3:H14)

Sheet Product Deep Dive
A1: PRODUCT DEEP DIVE | Revenue, Units, Margin & Growth Analysis
A2: Product | B2: Category | C2: Q1 Units | D2: Q2 Units | E2: Q3 Units | F2: Q4 Units | G2: Total Units | H2: Avg Sell Price | I2: Total Revenue | J2: COGS (est) | K2: Gross Profit | L2: Gross Margin%
A3: Product A | B3: Software | C3: 407 | D3: 444 | E3: 481 | F3: 518 | G3: =SUM(C3:F3) | H3: 500 | I3: =G3*H3 | J3: 296000 | K3: =I3-J3 | L3: =IFERROR(K3/I3,0)
A4: Product B | B4: Hardware | C4: 312 | D4: 340 | E4: 369 | F4: 397 | G4: =SUM(C4:F4) | H4: 500 | I4: =G4*H4 | J4: 390500 | K4: =I4-J4 | L4: =IFERROR(K4/I4,0)
A5: Product C | B5: Service | C5: 462 | D5: 504 | E5: 546 | F5: 588 | G5: =SUM(C5:F5) | H5: 500 | I5: =G5*H5 | J5: 262500 | K5: =I5-J5 | L5: =IFERROR(K5/I5,0)
A6: Product D | B6: Software | C6: 215 | D6: 235 | E6: 254 | F6: 274 | G6: =SUM(C6:F6) | H6: 500 | I6: =G6*H6 | J6: 186200 | K6: =I6-J6 | L6: =IFERROR(K6/I6,0)
A7: Product E | B7: Hardware | C7: 367 | D7: 400 | E7: 434 | F7: 467 | G7: =SUM(C7:F7) | H7: 500 | I7: =G7*H7 | J7: 501000 | K7: =I7-J7 | L7: =IFERROR(K7/I7,0)
A8: Product F | B8: Service | C8: 167 | D8: 182 | E8: 197 | F8: 212 | G8: =SUM(C8:F8) | H8: 500 | I8: =G8*H8 | J8: 106400 | K8: =I8-J8 | L8: =IFERROR(K8/I8,0)
A9: Product G | B9: Software | C9: 517 | D9: 564 | E9: 611 | F9: 658 | G9: =SUM(C9:F9) | H9: 500 | I9: =G9*H9 | J9: 352500 | K9: =I9-J9 | L9: =IFERROR(K9/I9,0)
A10: Product H | B10: Hardware | C10: 129 | D10: 141 | E10: 153 | F10: 165 | G10: =SUM(C10:F10) | H10: 500 | I10: =G10*H10 | J10: 153400 | K10: =I10-J10 | L10: =IFERROR(K10/I10,0)
A11: Product I | B11: Service | C11: 246 | D11: 268 | E11: 291 | F11: 313 | G11: =SUM(C11:F11) | H11: 500 | I11: =G11*H11 | J11: 123200 | K11: =I11-J11 | L11: =IFERROR(K11/I11,0)
A12: Product J | B12: Software | C12: 303 | D12: 331 | E12: 358 | F12: 386 | G12: =SUM(C12:F12) | H12: 500 | I12: =G12*H12 | J12: 241500 | K12: =I12-J12 | L12: =IFERROR(K12/I12,0)
A13: TOTAL | C13: =SUM(C3:C12) | D13: =SUM(D3:D12) | E13: =SUM(E3:E12) | F13: =SUM(F3:F12) | G13: =SUM(G3:G12) | H13: =SUM(H3:H12) | I13: =SUM(I3:I12) | J13: =SUM(J3:J12) | K13: =SUM(K3:K12) | L13: =IFERROR(K13/I13,0)

Sheet ⚙️ Settings
A1: DASHBOARD SETTINGS & ASSUMPTIONS
A3: Setting | B3: Value | C3: Description
A4: Commission Rate | B4: 0.08 | C4: % of revenue paid to reps
A5: Revenue Target (Annual) | B5: 12000000 | C5: Full year company target
A6: Growth Rate Assumption | B6: 0.12 | C6: YoY growth expectation
A7: Avg Deal Size Target | B7: 35000 | C7: Target average deal value
A8: Pipeline Coverage Ratio | B8: 3 | C8: Pipeline / Quota multiplier
A9: Win Rate Target | B9: 0.3 | C9: Expected % of deals won
A10: Avg Sales Cycle Target | B10: 45 | C10: Days from prospect to close
A11: Discount Cap | B11: 0.15 | C11: Max allowable discount %
A12: Q1 Weight | B12: 0.22 | C12: % of annual revenue in Q1
A13: Q2 Weight | B13: 0.24 | C13: % of annual revenue in Q2
A14: Q3 Weight | B14: 0.26 | C14: % of annual revenue in Q3
A15: Q4 Weight | B15: 0.28 | C15: % of annual revenue in Q4
